{"name": "test_print15", "status": "failed", "statusDetails": {"message": "AssertionError: assert '1 function' in '2 function call'", "trace": "def test_print15():\n        flag = '2 function call'\n        printknow1()\n        printknow3()\n>       assert '1 function' in flag\nE       AssertionError: assert '1 function' in '2 function call'\n\napiauto\\test_doit5.py:30: AssertionError"}, "start": 1685195446641, "stop": 1685195446646, "uuid": "e9101b07-351c-48bb-a2b2-fe41893f6edd", "historyId": "004f2fb62e99c49c3bb45e229dfbc5b0", "testCaseId": "8eab7231fbfecee1cbcaaa83ca35650c", "fullName": "apiauto.test_doit5#test_print15", "labels": [{"name": "parentSuite", "value": "apiauto"}, {"name": "suite", "value": "test_doit5"}, {"name": "host", "value": "zhangtaopc"}, {"name": "thread", "value": "11624-MainThread"}, {"name": "framework", "value": "pytest"}, {"name": "language", "value": "cpython3"}, {"name": "package", "value": "apiauto.test_doit5"}]}